Failure # 1 (occurred at 2024-02-02_20-45-30)
[36mray::_Inner.train()[39m (pid=16414, ip=172.24.28.118, actor_id=58d246c2016745b95b21273601000000, repr=TorchTrainer)
  File "/home/tc/miniconda3/envs/mls/lib/python3.10/site-packages/ray/tune/trainable/trainable.py", line 342, in train
    raise skipped from exception_cause(skipped)
  File "/home/tc/miniconda3/envs/mls/lib/python3.10/site-packages/ray/train/_internal/utils.py", line 43, in check_for_failure
    ray.get(object_ref)
ray.exceptions.RayTaskError(AttributeError): [36mray::_RayTrainWorker__execute.get_next()[39m (pid=16482, ip=172.24.28.118, actor_id=7633bb4ad93cfe8cf28b751e01000000, repr=<ray.train._internal.worker_group.RayTrainWorker object at 0x7f1ac3776c20>)
  File "/home/tc/miniconda3/envs/mls/lib/python3.10/site-packages/ray/train/_internal/worker_group.py", line 33, in __execute
    raise skipped from exception_cause(skipped)
  File "/home/tc/miniconda3/envs/mls/lib/python3.10/site-packages/ray/train/_internal/utils.py", line 118, in discard_return_wrapper
    train_func(*args, **kwargs)
  File "/tmp/ipykernel_9950/3898995308.py", line 64, in train_loop_per_worker
    train_ds = session.get_dataset_shared("train")
AttributeError: module 'ray.train.session' has no attribute 'get_dataset_shared'
